Workbook
Name Accrued_Physical: [2]ImpAnalysis!$I$26
Name Actual_Age: [2]Inputs!$C$159
Name Actual_Taxes: [2]Tax!$G$21
Name Adj_Pro_Assessed_Val: [2]Tax!$K$12
Name AdjCatNo: '[2]IS Grid'!$A$81
Name Ambient_Area: [2]Inputs!$C$96
Name AmtBdgt: [3]OpActuals!$I:$I
Name AMTY1: [3]OpActuals!$C:$C
Name AMTY2: [3]OpActuals!$D:$D
Name AMTY3: [3]OpActuals!$E:$E
Name AMTY4: [3]OpActuals!$F:$F
Name AMTY5: [3]OpActuals!$H:$H
Name AnalysisType: [4]Assumptions!$C$2:$C$3
Name Anchor_1_Name: [2]Inputs!$C$119
Name Anchor_1_SF: [2]Inputs!$C$120
Name Anchor_2_Name: [2]Inputs!$C$121
Name Anchor_2_SF: [2]Inputs!$C$122
Name Anchor_3_Name: [2]Inputs!$C$123
Name Anchor_3_SF: [2]Inputs!$C$124
Name Anchor_4_Name: [2]Inputs!$C$125
Name Anchor_4_SF: [2]Inputs!$C$126
Name Anchor_5_Name: [2]Inputs!$C$127
Name Anchor_5_SF: [2]Inputs!$C$128
Name Anchor_6_Name: [2]Inputs!$C$129
Name Anchor_6_SF: [2]Inputs!$C$130
Name Annual_Mkt_Rent: '[2]Mkt Rent'!$BE$85
Name Appraisal_Fee: [2]Inputs!$C$58
Name Appraiser: [2]Inputs!$C$9
Name Apt.Concessions: '[2]Dir Cap'!$H$8
Name Apt.Concessions.Percent: '[2]Dir Cap'!$E$8
Name Apt.LosstoLease: '[2]Dir Cap'!$H$7
Name Apt.LosstoLease.Percent: '[2]Dir Cap'!$E$7
Name Apt_Row_Cost: [2]Cost!#REF!
Name ARC.Homesites: '[1]ARC Financials'!$F$240
Name ARC.No: [1]Instructions!$B$3
Name ARC.PropAddress: '[1]ARC Property List'!$D$9:$D$67
Name ARC.PropCity: '[1]ARC Property List'!$E$9:$E$67
Name ARC.PropCode: '[1]ARC Property List'!$B$9:$B$67
Name ARC.PropName: '[1]ARC Property List'!$C$9:$C$67
Name ARC.PropState: '[1]ARC Property List'!$F$9:$F$67
Name ARC.PropZip: '[1]ARC Property List'!$G$9:$G$67
Name ARI: '[2]Dir Cap'!$H$9
Name ArrTot: [6]Assumptions!$F$9:$G$21
Name ArrTotal: [4]Assumptions!$F$9:$G$21
Name As_Is_Value: [2]Values!$M$21
Name bbDateOfValueEffectiveDate: '[7]Valuation Scenarios'!$D$85
Name bbDateReport: [7]Assignment!$B$44
Name bbMarketValues: '[7]Valuation Scenarios'!$D$76
Name bbPropertyOwner: [7]Assignment!$B$27
Name bbValuationType: '[7]Valuation Scenarios'!$D$79
Name bbValueConditionScen1: '[3]Valuation Scenarios'!$B$8
Name bbValueDateScen1: '[3]Valuation Scenarios'!$B$5
Name bbValueInterestScen1: '[3]Valuation Scenarios'!$B$7
Name bbValueNameScen1: '[3]Valuation Scenarios'!$B$4
Name Building_Area: [2]Inputs!$C$146
Name Building_Class_List: [2]InputsRangeNames!$J$4:$J$8
Name Building_Class_Value: [2]InputsRangeNames!$J$2
Name Building_Class_Value_List: [2]InputsRangeNames!$I$4:$I$8
Name caDeferredMaint: [3]Cost!$F$44
Name caLandValueRND: [3]LSaleAdj!$E$48

Sheet Property Info
A1: Account | B1: R0118932 | G1: Fill in Highlighted Fields
A2: Occ. Code | B2: 407 | G2: DO NOT UPDATE CELLS IN THIS BOX
A3: Number of Buildings | B3: 1
A4: GBA | B4: 187720
A5: Footprint | B5: 33950
A6: NRA | B6: 33750
A7: SF Basis | B7: GBA | C7: ←Dropdown | E7: GBA | F7: Gross Building Area
A8: Year Built | B8: 1999 | E8: NRA | F8: Net Renatable Area
A9: Condition | B9: Average | E9: GLA | F9: Gross Leasable Area
A10: Year/Condition | B10: 1999/Average
A11: Site Size | B11: 108316
A12: Acres | B12: =B11/43560
A13: Coverage Ratio | B13: =B5/B11
A14: Office % | B14: 0.052
A15: Type | B15: Distribution Warehouse
A16: Address | B16: 6245 Washington Street
A17: City | B17: Unincorporated Adams County, CO
A18: County | B18: Adams County
A19: Assumed Occupancy | B19: 1
A20: Assessor's Assigned Value | B20: 3916200
A21: Petitioner's Value | B21: 3060000
A22: Recent Sale Date | B22: 42675
A23: Recent Sale Price | B23: 2880000
A24: Sale Type | B24: Investment
A25: Value Premise | B25: Fee Simple
A26: Date of Value | B26: 44012
A27: Report Date | B27: 45127
A28: Hearing Date | B28: 45192
A29: Zoning | B29: I-1 (Light Industrial)
A30: Zoning Authority | B30: Adams County

Sheet FE
A1: Note: | B1: FILL ONLY HIGHLIGHTED CELLS
B3: EXECUTIVE SUMMARY
B4: Account Number | C4: ='Property Info'!B1
B5: Address | C5: ='Property Info'!B16
B6: County | C6: ='Property Info'!B18
B7: City, State | C7: ='Property Info'!B17
B8: Effective Date | C8: ='Property Info'!B26
B9: Appraisal Date | C9: ='Property Info'!B27
B10: Hearing Date | C10: ='Property Info'!B28
B12: Property Type | C12: ='Property Info'!B15
B13: Property Size
B14: ='Property Info'!B7 | C14: =IF(B14="GBA", 'Property Info'!B4,IF(B14="NRA",'Property Info'!B6,'Property Info'!B4))
B15: Number of Buildings | C15: ='Property Info'!B3
B16: Year Built/Condition | C16: ='Property Info'!B10
B17: Condition | C17: Average
B18: Site Size (SF) | C18: ='Property Info'!B11
B19: Property Rights Appraised | C19: ='Property Info'!B25
B20: Assumed Occupancy | C20: ='Property Info'!B19
B21: Stabilized Occupancy | C21: ='Income Approach'!D22
D23: PETITION SCENARIO
E24: $ | F24: $/SF
D25: Assessor's Assigned Value | E25: ='Basic Sales Grid'!D51 | F25: =E25/C14
D26: Petitioner’s Requested Value | E26: ='Basic Sales Grid'!D52 | F26: =E26/C14
G28: APPRAISAL INFORMATION
G29: Intended User | H29: Adams County Board of Equalization, Adams County Attorney, Colorado Board of Assessment Appeals
H30: =clCompanyAddressStreet1&", "&clCompanyAddressStreet2
H31: =clCompanyAddressCity&", "&clCompanyAddressState&" "&clCompanyAddressZip
G32: Intended User(s) | H32: =H29
G33: Intended Use | H33: Aid in tax appeal decision
G34: Values Concluded | H34: Retrospective Market Value
G35: Property Rights Appraised / Premise | H35: Retrospective Market Value of the Fee Simple interest in the subject property, As Is as of June 30, 2020
G36: Premise Summary | H36: Retrospective Market Value As Is - June 30, 2020
G37: Date of Inspection | H37: 45079
G38: Report Date | H38: ='Property Info'!B27
G39: Marketing Time | H39: 12 months
G40: Exposure Time | H40: 12 months
G41: Owner of Record
G42: Property Contact(s) | H42: Mr. Patrick de Jongh and Mr. Michael Kaufman, taxpayer representatives, were interviewed by phone and email throughout the appraisal process and intended our inspection of the subject property.
G43: Most Probable Purchaser | H43: =pdMostProbablePurchaser
G44: Highest and Best Use
...

Sheet Market Neighborhood
B2: MARKET DATA
B3: Surrounding Area | C3: Industrial | D3: Market Trend | E3: Growth
B4: Overall Real Estate Values | C4: Increasing | D4: Neighborhood Vacancy | E4: 0.053
B5: Predominant Property Use(s) | C5: Industrial Neighborhood Retail Lodging | D5: Estimated Marketing | E5: 12 months
D6: Estimated Exposure | E6: 12 months
B7: Market Subsector(s) | C7: Adams County | D7: Q1 2019-Q2 2020 | F7: ←Change this
B8: Vacancy - CoStar - Industrial 20,000 SF-50,000 SF | D8: 0.07 | F8: ←From Income
C9: Denver CBSA | D9: =D7 | F9: ←Change This
B10: Vacancy - CoStar - Industrial 20,000 SF-50,000 SF | D10: 0.043 | F10: ←From Income
F11: NEIGHBORHOOD DATA
F12: Market Area Comments | G12: The subject property is located north of East 62nd Avenue, approximately 289 feet west of Washington Street, in unincorporated Adams County, Colorado. The immediate area is developed with light to medium intensity industrial properties, similar to the subject. The majority of the area is zoned I-1 (Light Industrial), allowing for warehousing, storage, distribution, and light-intensity industrial activity. A visual inspection the neighborhood indicates significant new development and redevelopment over the past five years. Local street/sidewalk infrastructure and municipal services have also been updated over that time.
F13: Surrounding Uses | G13: North: | H13: Industrial Lots
G14: South: | H14: Light Industrial
G15: East: | H15: Industrial Storage Lot
G16: West: | H16: Light Industrial
F17: Property Contact Interview | G17: =clInspectionContactName
I18: CHANGE → | J18: Average Sale Price - Denver Market Industrial - 10,000 SF-50,000 SF | N18: Average Sale Price - Adams County Industrial - 10,000 SF-50,000 SF
J19: Period | K19: Avg. Price ($/SF) | L19: % Change - Q2 2020 | M19: ←CHANGE → | N19: Period | O19: Avg. Price ($/SF) | P19: % Change - Q2 2020
I20: Pase from CoStar→ | J20: 2023 Q2 QTD | K20: 147 | N20: 2023 Q2 QTD | O20: 147
J21: 2023 Q1 | K21: 143 | L21: =($C$18-K21)/K21 | N21: 2023 Q1 | O21: 143
J22: 2022 Q4 | K22: 142 | L22: =($C$18-K22)/K22 | N22: 2022 Q4 | O22: 142
J23: 2022 Q3 | K23: 141 | L23: =($C$18-K23)/K23 | N23: 2022 Q3 | O23: 141
J24: 2022 Q2 | K24: 139 | L24: =($C$18-K24)/K24 | N24: 2022 Q2 | O24: 139
J25: 2022 Q1 | K25: 138 | L25: =($C$18-K25)/K25 | N25: 2022 Q1 | O25: 138
J26: 2021 Q4 | K26: 137 | L26: =($C$18-K26)/K26 | N26: 2021 Q4 | O26: 137
J27: 2021 Q3 | K27: 136 | L27: =($C$18-K27)/K27 | N27: 2021 Q3 | O27: 136
J28: 2021 Q2 | K28: 135 | L28: =($C$18-K28)/K28 | N28: 2021 Q2 | O28: 135
J29: 2021 Q1 | K29: 134 | L29: =($C$18-K29)/K29 | N29: 2021 Q1 | O29: 134
J30: 2020 Q4 | K30: 132 | L30: =($C$18-K30)/K30 | N30: 2020 Q4 | O30: 132
J31: 2020 Q3 | K31: 131 | L31: =($C$18-K31)/K31 | N31: 2020 Q3 | O31: 131
J32: 2020 Q2 | K32: 130 | L32: =($C$18-K32)/K32 | N32: 2020 Q2 | O32: 130
J33: 2020 Q1 | K33: 129 | L33: =($C$18-K33)/K33 | N33: 2020 Q1 | O33: 129 | P33: =($G$18-O33)/O33
J34: 2019 Q4 | K34: 128 | L34: =($C$18-K34)/K34 | N34: 2019 Q4 | O34: 128 | P34: =($G$18-O34)/O34
J35: 2019 Q3 | K35: 127 | L35: =($C$18-K35)/K35 | N35: 2019 Q3 | O35: 127 | P35: =($G$18-O35)/O35
J36: 2019 Q2 | K36: 125 | L36: =($C$18-K36)/K36 | N36: 2019 Q2 | O36: 125 | P36: =($G$18-O36)/O36
J37: 2019 Q1 | K37: 124 | L37: =($C$18-K37)/K37 | N37: 2019 Q1 | O37: 124 | P37: =($G$18-O37)/O37

Sheet Site Information
B2: SITE DESCRIPTION OVERVIEW
B4: Location | C4: =FE!U99
B5: Account Number | C5: =FE!U103
B6: Legal Description | C6: =FE!U106
B7: Site Area
B8: Primary Site | C8: =FE!U108 | D8: =FE!V108
B9: Excess Land | C9: =FE!U109 | D9: =FE!V109
B10: Surplus Land | C10: =FE!U110 | D10: =FE!V110
B11: Total | C11: =FE!U111 | D11: =FE!V111
B12: Configuration | C12: Generally rectangular site with street access from West 62nd Avenue and Washington St., via an apparent access easement with the adjacent property to the east.
B13: Topography | C13: Generally Level
B14: Drainage | C14: Appears adequate
B15: Utilities/Municipal Services | C15: Typical utilities and municipal services available to site.
B16: Floodplain | C16: Zone | D16: Map | E16: Date
C17: Zone X (Unshaded) | D17: 08001C0333H | E17: 39146 | I17: Zone A | J17: Zone X (Shaded)
C18: Zone X (unshaded) is a Non-Special Flood Hazard Area (NSFHA) of minimal flood hazard, usually depicted on Flood Insurance Rate Maps (FIRM) as above the 500-year flood level. This is an area in a low to moderate risk flood zone that is not in any immediate danger from flooding caused by overflowing rivers or hard rains. In communities that participate in the National Flood Insurance Program (NFIP), flood insurance is available to all property owners and renters in this zone.
B19: Census Tract No. | C19: =pdCensusTract
B21: SITE DESCRIPTION OVERVIEW - CONTINUED
B22: Soil/Subsoil Conditions | C22: We did not receive nor review a soil report. However, we assume that the soil's load-bearing capacity is sufficient to support existing structure(s). We did not observe any evidence to the contrary during our physical inspection of the property.
B23: Environmental Concerns | C23: No unusual conditions observed. No studies provided. Site is assumed to be free of any environmental concerns.
B24: Land Use Restrictions | C24: No atypical easements or encumbrances noted. Typical access easement appears to exist along the north boundary of the adjacent property to the east, providing access to the subject from Washington Street. Signage directs deliveries to access the subject from noted access road.
B25: Hazards Nuisances | C25: None noted
B26: Frontage | C26: West 62nd Avenue
B27: Access | C27: West 62nd Avenue (direct), Washington Street (via apparent access easement to the east)
B28: Visibility | C28: Unobstructed: West 62nd Ave. Obstructed: Washington Street - through adjacent parcel.
B29: Surrounding Land Uses | C29: Light to medium-intensity industrial
B30: Enterprise Zone | C30: None noted
B31: Traffic Counts | C31: West 62nd Ave: 5,235 VPD, Washington Street: 13,501 VPD Per CoStar (Jan. 2022 Est.)
B32: Transportation Facilities | C32: Northbound and southbound bus stops located along Washington Street, at E. 62nd Ave.
B33: Comments | C33: Light industrial property located in an area of generally similar industrial development. Access to the property available from E. 62nd Ave. and Washington St. with visibility available from both thoroughfares. Convenient access to Interstate 25, Interstate 76, and Interstate 270, all less than one mile from the subject property. No atypical easements or encumbrances were noted at the property during the appraiser's inspection.
H35: ZONING
H36: Designation | I36: I-1
H37: Description | I37: Industrial-1 (Light Industrial)
H38: Zoning Intent | I38: The purpose of the Industrial‐1 District is to provide a general commercial and limited industrial district designed to provide for a variety of compatible business, warehouse, wholesale, offices and very limited industrial uses. Special uses are permitted in an Industrial‐1 District, subject to the issuance of a Special Use Permit from the Board of Adjustment. Temporary uses are permitted in the Industrial‐1 District, subject to the issuance of a Temporary Use Permit from the Director of Community and Economic Development.
H39: Compliance | I39: The subject is a legal confirming use in the I-1 zoning designation.
H40: ZONING REQUIREMENTS
H41: Min. Lot Size: | I41: 1 Acre
H42: Min. Lot Width: | I42: 100 Feet
H43: Setbacks:
H44: Front | I44: 25 Feet
...

Sheet Improvements
B2: =IF(OR(pdGenPropUse2="",pdGenPropUse2=0),"GENERAL DESCRIPTION OVERVIEW", "GENERAL DESCRIPTION OVERVIEW - "&UPPER(pdGenPropUse))
B3: Address | C3: ='Property Info'!B16
C4: ='Property Info'!B17
B5: Property Description | C5: =FE!U100
B6: Year Built | C6: ='Property Info'!B8
B7: Year Renovated | C7: =FE!U116
B8: Number of Buildings | C8: =FE!U120
B9: Number of Stories | C9: 1
B10: Total Number of Units | C10: =FE!U126
B11: Building Construction Class | C11: C/S
B12: Net Rentable Area | C12: =FE!U124
B13: Gross Leasable Area | C13: =FE!U122
B14: + Clubhouse | C14: =pdBldgAreaClubhouse
B15: + Others(s) | C15: =pdBldgAreaOther
B16: Mezzanine Area | C16: Small structural mezzanine located atop a temporary structure in the warehouse. Not included in the total GBA, considered an amenity of the property.
B17: Building Footprint | C17: ='Property Info'!B5
B18: Bay Depth | C18: =pdBayDepth
B19: LEED Ratio | C19: =pdLEEDRating
B20: Floor-Area Ratio | C20: =pdFAR
B21: Elevator(s) | C21: None
B22: Ceiling Heights | C22: 14'-23' (average 18')
B23: Utility Metering | C23: Master metered
B24: Density (Units/Acre) | C24: =C10/'Site Information'!C11
B25: Coverage Ratio | C25: =C17/'Site Information'!C11
B26: Land-to-Building Ratio | C26: ='Site Information'!C11/Improvements!C13
B27: Ingress/Egress | C27: Typical pedestrian entrances and loading doors along building perimeter.
B28: Percentage Office Build-Out | C28: ='Property Info'!B14
B29: Clear Height | C29: 12'-20'
B30: Power | C30: Assumed adequate for industrial use.
B31: Loading Doors
B32: Dock High | C32: 3
B33: Roll-Up | C33: 2
B34: Rail Access | C34: None
B35: Storage Yard | C35: Fenced storage yard located on the northwestern portion of the property.
B36: Truck Court | C36: Truck loading/unloading along the west and northeast building elevations.
B37: Parking
B38: Surface Parking Spaces | C38: 71
B39: Other | C39: 0
B40: Garages | C40: 0
B41: Total Parking Spaces | C41: =SUM(C38:C40)
...

Sheet H&BU
C1: NOTE: Most of the below text is standard boilerplate and should remain the same. Read through and change only the descriptions as they pertain to your property.
B3: AS IF VACANT
B4: Legally | C4: Legal restrictions include deed restrictions, CC&R’s, lease encumbrances, zoning requirements, building codes, historic district controls and environmental regulations, and were previously analyzed to determine legally permitted uses. Legally, the subject is zoned I-1 (Light Industrial). The purpose of the Industrial‐1 District is to provide a general commercial and limited industrial district designed to provide for a variety of compatible business, warehouse, wholesale, offices and very limited industrial uses. Special uses are permitted in an Industrial‐1 District, subject to the issuance of a Special Use Permit from the Board of Adjustment. Temporary uses are permitted in the Industrial‐1 District, subject to the issuance of a Temporary Use Permit from the Director of Community and Economic Development. Allowable uses include but are not limited to storage, distribution, wholesale, office/flex, warehousing, maintenance, and light manufacturing.
B5: Physically | C5: Size, shape, topography, soil condition, availability of utilities, transportation access, surrounding uses, and locational characteristics were previously analyzed to determine which legal land uses are physically possible and which are best to conform to the physical and locational aspects of the site and its setting with respect to the neighborhood and community. Overall, the physical site attributes result in adequate utility, and the property could be developed with a variety of legally-conforming uses. Given the surrounding uses and location, the site is best suited for light industrial use.
B6: Financially | C6: Financial feasibility is determined by the relationship of supply and demand for the legally probable land uses versus the cost to create them. The market analysis section reveals that industrial uses in the subject's market are generally stabilized. Ongoing industrial development during the period in question throughout the market area serve as direct evidence that new industrial development was financially feasible at this time. Comparisons of rental rates, operating expenses and construction costs indicate the subject property would have been capable of providing an adequate return on investment to warrant new industrial development in the market. This assertion is supported by the fact that the property has the potential to generate rental income as shown in the income approach. Therefore, industrial use is considered financially feasible.
B7: Maximally | C7: The final test of highest and best use of the site as vacant is that the use be maximally productive, yielding the highest return to the land. In order to determine the maximally productive use, a comparison of rental rates, occupancy, operating expenses, and rates of return for the financially feasible uses have been made. Based on this analysis, light industrial use renders the highest residual land value; therefore, light industrial development on the subject's site is the maximally productive use of the subject as vacant.
B11: AS IMPROVED
B12: Legally | C12: The subject is a legal conforming use in the I-1 zoning district. No other known legal encumbrances exists that limit use or function on the improved property.
B13: Physically | C13: The subject is currently improved with a 33,950 square foot industrial building, located on a 2.49-acre site that conforms to its surrounding uses. Continued used of the improvements for industrial use is physically possible.
B14: Financially | C14: Financial feasibility as an income-producing investment is based on the amount of rental income it can generate net of the required operating expenses. If the resulting net operating income motivates continued operation, then the land is being put to a productive and financially feasible use. The subject is capable of producing positive net cash flow to an investor. The existing improvements provide contributory value to the site, and there is no alternate use that would result in a greater value. Therefore, utilization of the existing improvements is financially feasible.
B15: Maximally | C15: The maximally productive use should conform to neighborhood trends and be consistent with existing nearby land uses. The single use that produces the greatest return on investment and usually the highest price and value is typically the highest and best use. As shown in the applicable valuation sections, properties like the subject have been acquired and continue to be used for industrial use. None of the comparable properties were acquired for conversion to an alternative use. This provides evidence suggesting that the current industrial use is maximally productive.

Sheet Final Value
C2: VALUE INDICATIONS
C3: As Is - Land Value Only
C4: Sales Comparison Approach | D4: ='Land Sales'!C66 | E4: =D4/'Property Info'!B11 | F4: Per Square Foot (LA)
C5: Value Conclusion - As Is | D5: =D4 | E5: =E4 | F5: =F4
C6: As Is - Retrospective Market Value - Fee Simple Estate
C7: Cost Approach | D7: Not Developed
C8: Sales Comparison Approach | D8: ='Basic Sales Grid'!D46 | E8: =D8/'Property Info'!B4 | F8: =FE!B14
C9: Income Capitalization Approach
C10: Direct Capitalization | D10: ='Income Approach'!C65 | E10: =D10/'Property Info'!B6 | F10: =F8
C11: Approach Reliance | D11: =IF(FE!B14="GBA",'Final Value'!C8,'Final Value'!C9)
C12: Value Conclusion | D12: =D10 | E12: =D12/'Property Info'!B4 | F12: =F8
C13: As Is
C14: Sales Comparison Approach | D14: ='Basic Sales Grid'!D46 | E14: =D14/'Property Info'!B4 | F14: Per Square Foot (GBA)
C15: Income Capitalization Approach
C16: Direct Capitalization | D16: 1445000 | E16: =D16/3112 | F16: =F14
C17: Approach Reliance | D17: Sales Comparison Approach
C18: ="Value Conclusion - "&PROPER(bbValueConditionScen1)&"" | D18: =D14 | E18: =E14 | F18: =F14
C19: Exposure Time | D19: 12 months
C20: Marketing Time | D20: 12 months
G21: MARKET VALUE CONCLUSION
G22: Appraisal Premise | H22: Interest Appraised | I22: Date of Value | J22: Value Conclusion
G23: Retrospective Market Value | H23: Fee Simple | I23: ='Property Info'!B26 | J23: =D12
G26: 6 MONTH LIQUIDATION VALUE CONCLUSION
G27: Appraisal Premise | H27: Interest Appraised | I27: Date of Value | J27: Value Conclusion
G28: =bbValueNameScen1 | H28: Fee Simple | I28: 43132 | J28: 325000
G30: HYPOTHETICAL MARKET VALUE CONCLUSION (UNDERLYING LAND ONLY)
G31: Appraisal Premise | H31: Interest Appraised | I31: Date of Value | J31: Value Conclusion
G32: As If Vacant | H32: Fee Simple | I32: 43132 | J32: 200000
G34: PROSPECTIVE MARKET VALUE CONCLUSION
G35: Appraisal Premise | H35: Interest Appraised | I35: Date of Value | J35: Value Conclusion
G36: Upon Completion | H36: Fee Simple | I36: 43830 | J36: =D12

Sheet Land Sales
B1: NOTES:
B2: Change Highlighted fields only
B3: Change highlighted areas to WHITE when complete
B4: Check all cells for accuracy after completing
B5: Remember to spell check every worksheet as you go.
B7: COMPARABLE SALE ADJUSTMENT GRID
C8: Subject | D8: Sale 1 | F8: Sale 2 | H8: Sale 3 | J8: Sale 4 | L8: Sale 5
B9: Address | C9: ='Property Info'!B16 | E9: 3600 Chambers Road | G9: TBD - E 96th Avenue | I9: 2021 E 68th Avenue | K9: 6100 E 48th Avenue | L9: 10480-10555 West 63rd Place
B10: City, State | C10: ='Property Info'!B17 | E10: Aurora, CO | G10: Commerce City, CO | I10: Denver, CO | K10: Denver, CO | L10: Arvada, CO
B11: Account/Parcel Number | C11: ='Property Info'!B1 | E11: 1821-29-2-18-001 | G11: 1721-21-1-03-002 | I11: 1825-023-04-013 | K11: 1202-00-098-000 | L11: 39-091-07-003
B12: Property Type | C12: Industrial Land | E12: Industrial Land | G12: Industrial Land | I12: Industrial Land | K12: Industrial Land | L12: Commercial Land
B13: Sale Date | C13: N/A | E13: 43998 | G13: 43969 | I13: 43766 | K13: 43747 | L13: Under Contract
B14: Sale Price | C14: N/A | E14: 1800000 | G14: 1100000 | I14: 1350000 | K14: 795000 | L14: TBD
B15: Listing Price | C15: N/A | E15: Not Reported | G15: 1224040 | I15: 1600000 | K15: Not Reported | L15: 500000
B16: Days On Market | C16: N/A | E16: Not Reported | G16: 1117 | I16: 259 | K16: Not Reported | L16: 725
B17: Data Source | C17: Assessor, appraiser measurements | E17: Costar, Assessor Data, Deed, Troy DeVos (Buyer Representative) | G17: CoStar, Assessor Data, Listing Broker (Phil Foster & Co.) | I17: CoStar, Assessor Data, Listing Broker (Mark Goodman/Goodman Commercial) | K17: CoStar, Denver Assessor, Deed, Loan | L17: CoStar, Assessor, Listing
B18: Grantor | C18: TBD | E18: Josef Reith | G18: Josef Reith | I18: Josef Reith | K18: Terry & Nikki LLC | L18: 4950
B19: Grantee | C19: TBD | E19: AGG Real Estate LLC | G19: AGG Real Estate LLC | I19: AGG Real Estate LLC | K19: Dilligaff Inc | L19: 4950
B20: Site Size (SF) | C20: ='Property Info'!B11 | E20: 175405 | G20: 122404 | I20: 95912 | K20: 91793 | L20: 47916
B21: Zoning | C21: ='Property Info'!B29 | E21: B-3 (Business/Commercial) | G21: PUD-I (Industrial) | I21: I-2 (General Industrial) | K21: I-B (General Industrial) | L21: B-2
B22: Comments | C22: Industrial land | E22: Commercial/industrial land, purchased for development. | G22: Industrial parcel purchased for development. | I22: Industrial parcel purchased for development. | K22: Industrial parcel purchased for development. | L22: Commercial lot purchased for re-development. Formerly a mini-golf center.
B23: Unadjusted Price Per SF | E23: =E14/E20 | G23: =G14/G20 | I23: =I14/I20 | K23: =K14/K20 | M23: =L15/L20
B24: Quantified Adjustments
B25: Property Rights Conveyed | C25: Fee Simple | D25: Fee Simple | E25: 0 | F25: Fee Simple | G25: 0 | H25: Fee Simple | I25: 0 | J25: Fee Simple | K25: 0 | L25: Fee Simple
B26: Property Rights Conveyed Adjusted | E26: =IF(LEFT(CELL("format",E25),1)="P",E23*(1+E25),IF(LEFT(CELL("format",E25),1)="C",E23+E25)) | G26: =IF(LEFT(CELL("format",G25),1)="P",G23*(1+G25),IF(LEFT(CELL("format",G25),1)="C",G23+G25)) | I26: =IF(LEFT(CELL("format",I25),1)="P",I23*(1+I25),IF(LEFT(CELL("format",I25),1)="C",I23+I25)) | K26: =IF(LEFT(CELL("format",K25),1)="P",K23*(1+K25),IF(LEFT(CELL("format",K25),1)="C",K23+K25)) | M26: =IF(LEFT(CELL("format",M25),1)="P",M23*(1+M25),IF(LEFT(CELL("format",M25),1)="C",M23+M25))
B27: Financing | C27: N/A | D27: Market-Based | E27: 0 | F27: Market-Based | G27: 0 | H27: Market-Based | I27: 0 | J27: Market-Based | K27: 0 | L27: Market-Based | M27: 0
B28: Financing Adjusted | E28: =IF(LEFT(CELL("format",E27),1)="P",E26*(1+E27),IF(LEFT(CELL("format",E27),1)="C",E26+E27)) | G28: =IF(LEFT(CELL("format",G27),1)="P",G26*(1+G27),IF(LEFT(CELL("format",G27),1)="C",G26+G27)) | I28: =IF(LEFT(CELL("format",I27),1)="P",I26*(1+I27),IF(LEFT(CELL("format",I27),1)="C",I26+I27)) | K28: =IF(LEFT(CELL("format",K27),1)="P",K26*(1+K27),IF(LEFT(CELL("format",K27),1)="C",K26+K27)) | M28: =IF(LEFT(CELL("format",M27),1)="P",M26*(1+M27),IF(LEFT(CELL("format",M27),1)="C",M26+M27)) | R28: =0.25*J20
B29: Terms/Conditions of Sale | C29: N/A | D29: None | E29: 0 | F29: None | G29: 0 | H29: None | I29: 0 | J29: None | K29: 0 | L29: None | M29: 0
B30: Terms/Conditions of Sale Adjusted | E30: =IF(LEFT(CELL("format",E29),1)="P",E28*(1+E29),IF(LEFT(CELL("format",E29),1)="C",E28+E29)) | G30: =IF(LEFT(CELL("format",G29),1)="P",G28*(1+G29),IF(LEFT(CELL("format",G29),1)="C",G28+G29)) | I30: =IF(LEFT(CELL("format",I29),1)="P",I28*(1+I29),IF(LEFT(CELL("format",I29),1)="C",I28+I29)) | K30: =IF(LEFT(CELL("format",K29),1)="P",K28*(1+K29),IF(LEFT(CELL("format",K29),1)="C",K28+K29)) | M30: =IF(LEFT(CELL("format",M29),1)="P",M28*(1+M29),IF(LEFT(CELL("format",M29),1)="C",M28+M29))
B31: Expenditures After Sale | C31: N/A | D31: None | E31: 0 | F31: None | G31: 0 | H31: None | I31: 0 | J31: None | K31: 0 | L31: None | M31: 0
B32: Expenditures After Sale Adjusted | E32: =IF(LEFT(CELL("format",E31),1)="P",E30*(1+E31),IF(LEFT(CELL("format",E31),1)="C",E30+E31)) | G32: =IF(LEFT(CELL("format",G31),1)="P",G30*(1+G31),IF(LEFT(CELL("format",G31),1)="C",G30+G31)) | I32: =IF(LEFT(CELL("format",I31),1)="P",I30*(1+I31),IF(LEFT(CELL("format",I31),1)="C",I30+I31)) | K32: =IF(LEFT(CELL("format",K31),1)="P",K30*(1+K31),IF(LEFT(CELL("format",K31),1)="C",K30+K31)) | M32: =IF(LEFT(CELL("format",M31),1)="P",M30*(1+M31),IF(LEFT(CELL("format",M31),1)="C",M30+M31))
B33: Market Conditions | C33: N/A | D33: =D13 | E33: 0 | F33: =F13 | G33: 0 | H33: =H13 | I33: 0 | J33: =J13 | K33: 0 | L33: TBD | M33: 0
B34: Market Conditions Adjusted | E34: =IF(LEFT(CELL("format",E33),1)="P",E32*(1+E33),IF(LEFT(CELL("format",E33),1)="C",E32+E33)) | G34: =IF(LEFT(CELL("format",G33),1)="P",G32*(1+G33),IF(LEFT(CELL("format",G33),1)="C",G32+G33)) | I34: =IF(LEFT(CELL("format",I33),1)="P",I32*(1+I33),IF(LEFT(CELL("format",I33),1)="C",I32+I33)) | K34: =IF(LEFT(CELL("format",K33),1)="P",K32*(1+K33),IF(LEFT(CELL("format",K33),1)="C",K32+K33)) | M34: =IF(LEFT(CELL("format",M33),1)="P",M32*(1+M33),IF(LEFT(CELL("format",M33),1)="C",M32+M33))
B35: Total Quantified Adjustment | E35: =IFERROR(TEXT(E34-E23,"$#,##0.00")&CHAR(10)&" or "&CHAR(10)&TEXT((E34-E23)/E23,"0.00%"),0) | G35: =IFERROR(TEXT(G34-G23,"$#,##0.00")&CHAR(10)&" or "&CHAR(10)&TEXT((G34-G23)/G23,"0.00%"),0) | I35: =IFERROR(TEXT(I34-I23,"$#,##0.00")&CHAR(10)&" or "&CHAR(10)&TEXT((I34-I23)/I23,"0.00%"),0) | K35: =IFERROR(TEXT(K34-K23,"$#,##0.00")&CHAR(10)&" or "&CHAR(10)&TEXT((K34-K23)/K23,"0.00%"),0) | M35: =IFERROR(TEXT(M34-M23,"$#,##0.00")&CHAR(10)&" or "&CHAR(10)&TEXT((M34-M23)/M23,"0.00%"),0)
B36: Quantitatively Adjusted Price | E36: =E34 | G36: =G34 | I36: =I34 | K36: =K34 | M36: =M34
B37: Location | C37: ='Basic Sales Grid'!D28 | D37: Average | E37: 0 | F37: Average | G37: 0 | H37: Average | I37: 0 | J37: Fair | K37: 0.1 | L37: Below-Average | M37: 0.05
B38: Distance from Subject | C38: N/A | D38: 3 miles | F38: 3 miles | H38: 3 miles | J38: 1/4 mile | L38: Adjacent
B39: Surrounding Land Uses | C39: Retail, residential, developable land | D39: Retail, residential | F39: Retail, residential | H39: Retail, residential | J39: Retail, office, residential | L39: Retail, residential
B40: Quality/Condition of Surrounding Area | C40: Average to New | D40: Average to New | F40: Average to New | H40: Average to New | J40: Average to Very Good | L40: Average to Very Good
B41: Access to Commercial Services/Amenities | C41: Good | D41: Good | F41: Good | H41: Good | J41: Good | L41: Good
...

Sheet M&S Inputs
A1: MARSHALL AND SWIFT (MVS) COST INPUTS -- June 2024 Edition
B2: Field | C2: Value (Input) | D2: Unit | E2: MVS Reference / Notes | F2: Source
A3: STEP 1 -- BUILDING IDENTIFICATION
B4: MVS Section | C4: Section 14 | D4: -- | E4: Section 14: Garages, Industrials and Warehouses (June 2024 ed.). PRIOR EDITIONS used Section 18 for industrials; June 2024 renumbered. Section 18 in June 2024 = Schools. | F4: MVS Sec.99 p.3
B5: Occupancy Code | C5: Occ. 406 | D5: -- | E5: 406 = Storage Warehouses. Other codes: 401 Service Garages, 402 Auto Dealerships, 403 Car Wash, 405 Commercial Garages, 407 Mfg. Light, 408 Mfg. Heavy. | F5: MVS Sec.14 p.26
B6: Building Class | C6: C | D6: -- | E6: A = Fire resistive concrete. B = Masonry/steel. C = Combustible frame. D = Wood frame/metal. S = Pre-engineered metal building. | F6: MVS Sec.14
B7: Quality | C7: Average | D7: -- | E7: Quality tiers: Low Cost | Average | Good | Excellent. Select relative to class standard. | F7: MVS Sec.14 p.26
B8: City / Local Area (for LAM lookup) | C8: Colorado Statewide | D8: -- | E8: Pick city from dropdown → auto-fills Local Area Multiplier (C19). Adams County: use 'Colorado Statewide' or 'Denver'.
A9: STEP 2 -- BASE COST AND SPRINKLER COST (per SF)
B10: Building Area (SF) [auto from Property Info] | C10: ='Property Info'!B4 | D10: SF | E10: Auto-linked from Property Info sheet. Used to interpolate sprinkler cost from TABLE D.
B11: Selected: Section / Class / Quality | C11: =C4&" / Occ. "&C5&" / Class "&C6&" / "&C7 | D11: -- | E11: Concatenated from Step 1 selections above -- confirms your lookup inputs.
B13: >>> Base cost auto-calculated from occupancy / class / quality above <<<
B14: Base Cost per SF [-> Cost Approach D6] | C14: =IFERROR(IF(C5="Occ. 406",INDEX($C$42:$C$62,MATCH(C6&"~"&C7,$D$42:$D$62,0)),INDEX($C$116:$C$123,MATCH(C6&"~"&C7,$D$116:$D$123,0))),"") | D14: $/SF | E14: Enter value from TABLE A (Occ.406 Storage Warehouse). Example: Class D / Average = .50/SF. Class D / Good = .00/SF. | F14: MVS Sec.14 p.26 (Feb 2024) | H14: Sprinkler Quality
B15: Sprinkler Add-On per SF (Wet System) [-> D7] | C15: =IFERROR(INDEX($B$98:$E$105,MATCH(C10,$A$98:$A$105,1),MATCH(H15,$B$97:$E$97,0)),"") | D15: $/SF | E15: From TABLE D. Interpolate by building area and quality. Example: 40,000 SF / Low Cost = .04/SF. Enter 0 if no sprinklers. | F15: MVS Sec.14 p.37 (Feb 2024) | H15: Average
A17: STEP 3 -- MULTIPLIERS
B18: Current Cost Multiplier [-> D15] | C18: =IFERROR(INDEX($B$81:$F$81,MATCH("Class "&IF(C6="C-Mill","C",IF(C6="D-Pole","D",C6)),$B$78:$F$78,0)),"") | D18: multiplier | E18: From TABLE C. Section 14 (eff. Feb 2024), Jan 2025 update. EASTERN region (Colorado): A=1.02, B=1.04, C=1.03, D=1.01, S=1.03. | F18: MVS Sec.99 p.3 (Jan 2025)
B19: Local Area Multiplier [-> D16] | C19: =IFERROR(INDEX($B$86:$F$93,MATCH(C8,$A$86:$A$93,0),MATCH("Class "&IF(C6="C-Mill","C",IF(C6="D-Pole","D",C6)),$B$85:$F$85,0)),"") | D19: multiplier | E19: From TABLE C2 (Colorado cities). Statewide D=1.01. Denver=1.00, Boulder=0.97, Fort Collins=0.99, Greeley=0.99, Pueblo=0.95. | F19: MVS Sec.99 p.7 (Jan 2025)
B20: Area Multiplier (avg of 2 size factors) [-> D17] | C20: =(E20+E21)/2 | D20: Area Factor 1 -> | E20: 0.876 | F20: Look up your SF in the size-adjustment table (Sec.14 p.25). Average two bracketing entries.
D21: Area Factor 2 -> | E21: 0.87
B22: Story Height Multiplier [-> D18] | C22: =IF(G22="",1,IFERROR(VLOOKUP(G22,$A$127:$B$142,2,TRUE),1)) | D22: multiplier | E22: From TABLE B. Base = 14 ft. Common: 20ft=1.133, 18ft=1.086, 16ft=1.041, 14ft=1.000, 12ft=0.960, 10ft=0.921. Enter actual clear eave height. | F22: Avg Eave/Wall Ht (ft) → | G22: 40
A24: STEP 4 -- SITE IMPROVEMENT RATES
B25: Asphalt Paving per SF [-> D22] | C25: 3.1 | D25: $/SF | E25: Sec.66 p.1 (Dec 2023). Large areas >3,000 SF: 4-inch asphalt .92-.51/SF, avg .10/SF. | F25: MVS Sec.66 p.1 (Dec 2023)
B26: Concrete Paving per SF [-> D24] | C26: 5.51 | D26: $/SF | E26: Sec.66 p.1 (Dec 2023). Large areas: 6-inch concrete .66-.71/SF, avg .51/SF. | F26: MVS Sec.66 p.1 (Dec 2023)
B27: Parking Striping per Space [-> D23] | C27: 20 | D27: $/space | E27: Market-derived. No MVS table. Typical range -/space. Adjust for painted vs. thermoplastic. | F27: Market data
B28: Landscaping per SF (lot area) [-> D27] | C28: 5.5 | D28: $/SF lot | E28: Sec.66 landscaping or market estimate. Applied to landscaped lot area. Adjust for density of planting and irrigation. | F28: MVS Sec.66 / market
A30: STEP 5 -- COST ADJUSTMENTS
B31: Indirect Costs % [-> C30] | C31: 0.1 | D31: % of construction | E31: Financing, permits, professional fees, insurance during construction. Typical 8%-15%. MVS default ~10%. | F31: MVS / market
B32: Entrepreneurial Profit % [-> C32] | C32: 0.15 | D32: % of (constr+indirect) | E32: Developer expected return above cost. Typical 10%-20%. MVS default ~15%. Adjust for market conditions. | F32: MVS / market
A34: STEP 6 -- DEPRECIATION OVERRIDES (enter 0 if none)
B35: Curable Deferred Maintenance ($) [-> F38] | C35: 0 | D35: $ | E35: Dollar cost to cure deferred items (roof, HVAC, etc.). Enter positive number. 0 = no curable items. | F35: Inspection / market
B36: Functional Obsolescence % [-> C43] | C36: 0 | D36: % of RCN | E36: Loss from design deficiencies (excess bays, substandard ceiling height, etc.). 0 = none. | F36: Market analysis
B37: External Obsolescence % [-> C44] | C37: 0 | D37: % of RCN | E37: Loss from external factors (market, economic, locational). 0 = none. | F37: Market analysis
A39: MVS QUICK-REFERENCE TABLES -- DO NOT EDIT (sourced from MVS June 2024 edition)
A40: TABLE A -- Occ. 406: Storage Warehouses | Base Cost per SF | MVS Sec.14, p.26 (Feb 2024)
A41: Class | B41: Quality | C41: $/SF | D41: Key (auto)
A42: A | B42: Good | C42: 137 | D42: A~Good
A43: A | B43: Average | C43: 101 | D43: A~Average
A44: A | B44: Low Cost | C44: 79.5 | D44: A~Low Cost
A45: B | B45: Good | C45: 121 | D45: B~Good
A46: B | B46: Average | C46: 88 | D46: B~Average
...

Sheet Cost Approach
A1: COST APPROACH | I1: NOTES
I2: Change Highlighted fields only
B3: COST APPROACH SUMMARY | I3: Change highlighted areas to WHITE when complete
B4: Replacement Cost New (RCN) | C4: Area (SF) | D4: $/SF | F4: Subtotal | G4: Total Cost | I4: Check all cells for accuracy after completing
B5: Building Improvements | I5: Remember to spell check every worksheet as you go.
B6: Base Cost | C6: ='Property Info'!B4 | D6: ='M&S Inputs'!C14 | F6: =C6*D6 | I6: LAND VALUE IS SET TO VALUE CONCLUDED IN THE LAND SALES WORKSHEET.
B7: Sprinklers | C7: =C6 | D7: ='M&S Inputs'!C15 | F7: =C7*D7 | I7: IF YOU ARE USING LAND VALUE FROM REALWARE, OVERWRITE THAT CELL WITH THE
B13: Subtotal | F13: =SUM(F6:F12) | I13: APPROPRIATE LAND VALUE.
B14: Multipliers
B15: Current Cost | D15: ='M&S Inputs'!C18
B16: Local Area | D16: ='M&S Inputs'!C19
B17: Area Multiplier | D17: ='M&S Inputs'!C20
B18: Story Height (Assumed 18' Average) | D18: ='M&S Inputs'!C22
B19: Product of Multipliers | F19: =ROUND(PRODUCT(D15:D18),3)
B20: Adjusted Base Building Cost | G20: =F19*F13
B21: Site Improvements (Component SF Based on Appraiser Measurement)
B22: Parking/Loading Areas (asphalt) | C22: 37800 | D22: ='M&S Inputs'!C25 | F22: =D22*C22
B23: Striping (Per Space) | C23: 71 | D23: ='M&S Inputs'!C27 | F23: =D23*C23
B24: Paving (concrete) | C24: =3564.94+334.9+942.42+495 | D24: ='M&S Inputs'!C26 | F24: =D24*C24
B25: Other1 | F25: =D25*C25
B26: Other2 | F26: =D26*C26
B27: Landscaping, Lighting, Other Site Improvements | C27: =27877.68+472.99 | D27: ='M&S Inputs'!C28 | F27: =D27*C27
B28: Total Site Improvements | G28: =SUM(F22:F27)
B29: Total Construction Costs | G29: =SUM(G20:G28)
B30: Plus Other Indirect Costs (% of Direct Costs) | C30: ='M&S Inputs'!C31 | G30: =G29*(C30)
B31: Subtotal Replacement Cost New (RCN) | G31: =SUM(G29:G30)
B32: Plus Entrepreneurial Profit (% of RCN) | C32: ='M&S Inputs'!C32 | G32: =G31*C32
B33: Total Replacement Cost New (RCN) | G33: =SUM(G31:G32)
B34: per square foot of gross building area | G34: =caRCN/10000
B36: Less Accrued Depreciation
B37: Physical
B38: Curable (Deferred Maintenance) | F38: ='M&S Inputs'!C35
B39: Incurable | U39: 251225
B40: Effective Age (Years) | C40: =Improvements!C98 | U40: 5000
B41: Economic Life | C41: =Improvements!C97 | U41: 138125
B42: Total Incurable Physical Depreciation | C42: =C40/C41 | F42: =G33*C42 | U42: 198000
B43: Functional Obsolescence | C43: ='M&S Inputs'!C36 | F43: =C43*caRCN | U43: =SUM(U39:U42)
B44: External Obsolescence | C44: ='M&S Inputs'!C37 | F44: =C44*caRCN
B45: Total | C45: =G45/caRCN | G45: =SUM(F38:F44)
B46: Depreciated Value of the Improvements | G46: =G33-G45
...

Sheet Construction Costs
B2: Subject's Budgeted Construction Costs
B3: Item | C3: Cost | D3: Cost PSF
B4: Site Inspection, Architectural & Engineering | C4: 208225 | D4: =C4/'Property Info'!$B$4
B5: Government Fees & Permits | C5: 406500 | D5: =C5/'Property Info'!$B$4
B6: Site Improvements | C6: 733000 | D6: =C6/'Property Info'!$B$4
B7: Off-Site Construction | C7: 105000 | D7: =C7/'Property Info'!$B$4
B8: Vertical Improvements | C8: 2150000 | D8: =C8/'Property Info'!$B$4
B9: Contractor Overhead & Profit | C9: 375000 | D9: =C9/'Property Info'!$B$4
B10: Indirect Costs | D10: =C10/'Property Info'!$B$4
B11: Total | C11: =SUM(C4:C10) | D11: =C11/'Property Info'!$B$4
F12: Comparable Constrution Cots
F13: Comparable | G13: 1 | H13: 2 | I13: 3 | J13: 4
F14: Location | G14: Metro Denver | H14: Metro Denver | I14: Metro Denver | J14: Metro Denver
F15: YOC | G15: 2015 | H15: 2016 | I15: 2019 | J15: 2019
F16: Property Type | G16: Franchise Daycare | H16: Franchise Daycare | I16: Franchise Daycare | J16: Franchise Daycare
F17: Total Direct Cost | G17: 255.16 | H17: 325.13 | I17: 420.5 | J17: 344.08

Sheet Export030823
B1: Property Address | C1: Property City | D1: Account/Parcel | E1: Property Type | F1: Sale Date | G1: Sale Price | H1: Price ($/SF) | I1: Asking Price | J1: DOM | K1: Building SF | L1: Land Area SF | M1: Property Rights Conveyed | N1: Financing | O1: Terms/ Conditions of Sale | P1: Expenditures After Sale | Q1: Market Conditions | R1: Location | S1: Property Size (SF) | T1: YOC / Condition | U1: Quality | V1: Land-To-Building Ratio | W1: Tenancy / Occupancy | X1: Functional Utility | Y1: Total Net Adj. | Z1: Adjusted Price ($/SF)
A2: A | B2: ='Property Info'!B16 | C2: ='Property Info'!B17 | D2: ='Property Info'!B1 | E2: ='Property Info'!B15 | F2: N/A | G2: N/A | H2: N/A | I2: N/A | J2: N/A | K2: =FE!C14 | L2: ='Property Info'!B11 | M2: ='Property Info'!B24 | N2: N/A | O2: N/A | P2: N/A | Q2: N/A | R2: Average | S2: =K2 | T2: ='Property Info'!B10 | U2: Average | V2: =L2/K2 | W2: Average | X2: Average | Y2: N/A | Z2: N/A
A3: 1 | B3: 9670 Dallas St (Condo) | C3: Henderson | D3: 1721-15-3-03-001 | E3: Industrial | F3: 44742 | G3: 630000 | H3: 210 | I3: 525000 | J3: 289 | K3: 3000 | M3: 0 | N3: 0 | O3: 0 | P3: 0 | Q3: 0 | R3: 0.05 | S3: -0.05 | T3: 0 | U3: 0 | V3: 0 | W3: 0 | X3: 0 | Y3: =SUM(M3:X3) | Z3: =H3+(H3*Y3)
A4: 2 | B4: 9652 Hanover Ct W | C4: Henderson | D4: 1721-15-0-11-005 | E4: Industrial | F4: 44637 | G4: 4600000 | H4: 197.87 | K4: 23248 | L4: 73704 | M4: 0 | N4: 0 | O4: 0 | P4: 0 | Q4: 0 | R4: 0 | S4: 0 | T4: 0 | U4: -0.1 | V4: 0 | W4: 0 | X4: 0 | Y4: =SUM(M4:X4) | Z4: =H4+(H4*Y4)
A5: 3 | B5: 9690 Dallas St (Condo) | C5: Henderson | D5: 1721-15-3-03-013 | E5: Industrial | F5: 44631 | G5: 525000 | H5: 175 | K5: 3000 | L5: 93218 | M5: 0 | N5: 0 | O5: 0 | P5: 0 | Q5: 0 | R5: 0 | S5: -0.05 | T5: 0 | U5: -0.05 | V5: 0.05 | W5: 0.05 | X5: 0 | Y5: =SUM(M5:X5) | Z5: =H5+(H5*Y5)
A6: 4 | B6: 9900 Emporia St (Part of a 2 Property Sale) | C6: Commerce City | D6: 1721-15-4-04-003 | E6: Industrial | F6: 44537 | G6: 9728033 | H6: 640 | K6: 15200 | L6: 487436 | M6: 0 | N6: 0 | O6: 0 | P6: 0 | Q6: 0.05 | R6: 0 | S6: 0 | T6: 0 | U6: 0 | V6: 0.05 | W6: 0 | X6: 0 | Y6: =SUM(M6:X6) | Z6: =H6+(H6*Y6)
A7: 5 | B7: 10400 E 102nd Ave | C7: Commerce City | D7: 1721-15-1-02-013 | E7: Industrial | F7: 44517 | G7: 13000000 | H7: 739.6 | K7: 17577 | L7: 700880
B8: Average | H8: =AVERAGE(H3:H7) | Z8: =AVERAGE(Z3:Z7)
B9: Median | H9: =MEDIAN(H3:H7) | Z9: =MEDIAN(Z3:Z7)
B10: Standard Dev. | H10: =_xlfn.STDEV.P(H3:H6) | Z10: =_xlfn.STDEV.P(Z3:Z6)
R12: Comp | S12: % Size Diff. | V12: LTB
R13: 1 | S13: =(K3-$K$2)/$K$2 | V13: =L3/K3
R14: 2 | S14: =(K4-$K$2)/$K$2 | V14: =L4/K4
R15: 3 | S15: =(K5-$K$2)/$K$2 | V15: =L5/K5
R16: 4 | S16: =(K6-$K$2)/$K$2 | V16: =L6/K6
R17: 5 | S17: =(K7-$K$2)/$K$2 | V17: =L7/K7

Sheet Basic Sales Grid
C2: COMPARABLE SALE ADJUSTMENT GRID
D3: Subject | E3: Sale 1 | F3: Sale 2 | G3: Sale 3 | H3: Sale 4 | I3: Sale 5 | J3: Listing 1
C4: Address | D4: =Export030823!B2 | E4: =Export030823!B3 | F4: =Export030823!B4 | G4: =Export030823!B5 | H4: =Export030823!B6 | I4: =Export030823!B7 | J4: 3555 West 144th Avenue
C5: City, State | D5: =Export030823!C2 | E5: =Export030823!C3 | F5: =Export030823!C4 | G5: =Export030823!C5 | H5: =Export030823!C6 | I5: =Export030823!C7 | J5: Broomfield
C6: Parcel Number | D6: =Export030823!D2 | E6: =Export030823!D3 | F6: =Export030823!D4 | G6: =Export030823!D5 | H6: =Export030823!D6 | I6: =Export030823!D7 | J6: 1573-173-14-002
C7: Property Type | D7: =Export030823!E2 | E7: =Export030823!E3 | F7: =Export030823!E4 | G7: =Export030823!E5 | H7: =Export030823!E6 | I7: =Export030823!E7 | J7: ST Daycare Building
C8: Sale Date | D8: N/A | E8: =Export030823!F3 | F8: =Export030823!F4 | G8: =Export030823!F5 | H8: =Export030823!F6 | I8: =Export030823!F7 | J8: TBD (Active Listing)
C9: Sale Price | D9: N/A | E9: =Export030823!G3 | F9: =Export030823!G4 | G9: =Export030823!G5 | H9: =Export030823!G6 | I9: =Export030823!G7 | J9: N/A
C10: Listing Price | D10: N/A | E10: =Export030823!I3 | F10: =Export030823!I4 | G10: =Export030823!I5 | H10: =Export030823!I6 | I10: =Export030823!I7 | K10: 6769231
C11: Days On Market | D11: N/A | E11: =Export030823!J3 | F11: =Export030823!J4 | G11: =Export030823!J5 | H11: =Export030823!J6 | I11: =Export030823!J7 | J11: 73
C12: Data Source | D12: Inspection, Lease, Site Plans, Assessor | E12: CoStar, Assessor, Deed | F12: CoStar, Assessor, Deed | G12: CoStar, Assessor, Deed | H12: CoStar, Assessor, Deed | I12: CoStar, Assessor, Offering Memorandum | J12: CoStar, Assessor, Offering Memorandum
C13: Property Size (SF) | D13: =Export030823!K2 | E13: =Export030823!K3 | F13: =Export030823!K4 | G13: =Export030823!K5 | H13: =Export030823!K6 | I13: =Export030823!K7 | J13: 10511
C14: Site Size (SF) | D14: =Export030823!L2 | E14: =Export030823!L3 | F14: =Export030823!L4 | G14: =Export030823!L5 | H14: =Export030823!L6 | I14: =Export030823!L7 | J14: 67954
C15: Parking Spaces | D15: 41 | J15: 28
C16: Comments | D16: Single-tenant daycare facility 100% leased long-term to KinderCare on a guaranteed net agreement. | J16: Single-tenant daycare facility 100% leased long-term to Little Sunshine's Playhouse and Preschool, a national tenant.
C17: Unadjusted Price Per SF | E17: =E9/E13 | F17: =F9/F13 | G17: =G9/G13 | H17: =H9/H13 | I17: =I9/I13 | K17: =K10/J13
C18: Quantified Adjustments
C19: Sale Type | D19: =Export030823!M2 | E19: =Export030823!M3 | F19: =Export030823!M4 | G19: =Export030823!M5 | H19: =Export030823!M6 | I19: =Export030823!M7 | J19: Leased Fee
C20: Financing | D20: Market Based | E20: =Export030823!N3 | F20: =Export030823!N4 | G20: =Export030823!N5 | H20: =Export030823!N6 | I20: =Export030823!N7 | K20: 0
C21: Terms/Conditions of Sale | D21: None | E21: =Export030823!O3 | F21: =Export030823!O4 | G21: =Export030823!O5 | H21: =Export030823!O6 | I21: =Export030823!O7 | J21: Active Listing | K21: -0.05
C22: Expenditures After Sale | D22: None | E22: =Export030823!P3 | F22: =Export030823!P4 | G22: =Export030823!P5 | H22: =Export030823!P6 | I22: =Export030823!P7 | K22: 0
C23: Market Conditions | D23: N/A | E23: =Export030823!Q3 | F23: =Export030823!Q4 | G23: =Export030823!Q5 | H23: =Export030823!Q6 | I23: =Export030823!Q7 | K23: 0
C24: Market Conditions Adjusted | E24: =IF(LEFT(CELL("format",E23),1)="P",E17*(1+E23),IF(LEFT(CELL("format",E23),1)="C",E17+E23)) | F24: =IF(LEFT(CELL("format",F23),1)="P",F17*(1+F23),IF(LEFT(CELL("format",F23),1)="C",F17+F23)) | G24: =IF(LEFT(CELL("format",G23),1)="P",G17*(1+G23),IF(LEFT(CELL("format",G23),1)="C",G17+G23)) | H24: =IF(LEFT(CELL("format",H23),1)="P",H17*(1+H23),IF(LEFT(CELL("format",H23),1)="C",H17+H23)) | I24: =IF(LEFT(CELL("format",I23),1)="P",I17*(1+I23),IF(LEFT(CELL("format",I23),1)="C",I17+I23)) | K24: =IF(LEFT(CELL("format",K23),1)="P",K17*(1+K23),IF(LEFT(CELL("format",K23),1)="C",K17+K23))
C25: Total Quantified Adjustment | E25: =SUM(E19:E23) | F25: =SUM(F19:F23) | G25: =SUM(G19:G23) | H25: =SUM(H19:H23) | I25: =SUM(I19:I23) | K25: =IFERROR(TEXT(K24-K17,"$#,##0.00")&CHAR(10)&" or "&CHAR(10)&TEXT((K24-K17)/K17,"0.00%"),0)
C26: Quantitatively Adjusted Price | E26: =E17+(E17*E25) | F26: =F17+(F17*F25) | G26: =G17+(G17*G25) | H26: =H17+(H17*H25) | I26: =I17+(I17*I25) | K26: =K24
C27: Qualitative Adjustments | K27: =SUM(K19:K25)+1
C28: =Export030823!R1 | D28: =Export030823!R2 | E28: =Export030823!R3 | F28: =Export030823!R4 | G28: =Export030823!R5 | H28: =Export030823!R6 | I28: =Export030823!R7 | J28: Good | K28: 0
C29: =Export030823!S1 | D29: =Export030823!S2 | E29: =Export030823!S3 | F29: =Export030823!S4 | G29: =Export030823!S5 | H29: =Export030823!S6 | I29: =Export030823!S7 | J29: =J13 | K29: 0
C30: =Export030823!T1 | D30: =Export030823!T2 | E30: =Export030823!T3 | F30: =Export030823!T4 | G30: =Export030823!T5 | H30: =Export030823!T6 | I30: =Export030823!T7 | J30: 2019 / Very Good | K30: 0
C31: =Export030823!U1 | D31: =Export030823!U2 | E31: =Export030823!U3 | F31: =Export030823!U4 | G31: =Export030823!U5 | H31: =Export030823!U6 | I31: =Export030823!U7 | J31: Good | K31: 0
C32: =Export030823!V1 | D32: =Export030823!V2 | E32: =Export030823!V3 | F32: =Export030823!V4 | G32: =Export030823!V5 | H32: =Export030823!V6 | I32: =Export030823!V7 | J32: =ROUND((J15/J13)*1000,2)& ":1,000 SF" | K32: 0
C33: =Export030823!W1 | D33: =Export030823!W2 | E33: =Export030823!W3 | F33: =Export030823!W4 | G33: =Export030823!W5 | H33: =Export030823!W6 | I33: =Export030823!W7 | J33: Good | K33: 0
C34: =Export030823!X1 | D34: =Export030823!X2 | E34: =Export030823!X3 | F34: =Export030823!X4 | G34: =Export030823!X5 | H34: =Export030823!X6 | I34: =Export030823!X7 | J34: Good | K34: 0
C35: Total Non Quantified Adj. | E35: =SUM(E28,E29,E30,E31,E32,E33,E34) | F35: =SUM(F28,F29,F30,F31,F32,F33,F34) | G35: =SUM(G28,G29,G30,G31,G32,G33,G34) | H35: =SUM(H28,H29,H30,H31,H32,H33,H34) | I35: =SUM(I28,I29,I30,I31,I32,I33,I34) | K35: =SUM(K28,K29,K30,K31,K32,K33,K34)
C36: Indication for Subject: | E36: =E26+(E26*E35) | F36: =F26+(F26*F35) | G36: =G26+(G26*G35) | H36: =H26+(H26*H35) | I36: =I26+(I26*I35) | K36: =IF(LEFT(CELL("format",K35),1)="P",K26*(1+K35),IF(LEFT(CELL("format",K35),1)="C",K26+K35))
C39: SALES COMPARISON APPROACH VALUE CONCLUSION
C40: Indicated Value per SF | D40: 120
C41: Building Area (SF) | D41: ='Property Info'!B4
C42: =IF(D43=0,"HIDE THIS ROW IF NO DEFERRED MAINTENANCE", "Indicated Value") | D42: =D40*D41
C43: Contract Price | D43: 0
...

Sheet Detailed Sales Grid
C2: COMPARABLE SALE ADJUSTMENT GRID
D3: Subject
C4: Address | D4: 5668 North Beeler Street
C5: City, State | D5: Denver, CO
C6: Parcel Number | D6: 1103-40-003-000
C7: Property Type | D7: Daycare Building
C8: Sale Date | D8: N/A
C9: Sale Price | D9: 6555000
C10: Listing Price | D10: 6555000
C11: Days On Market | D11: N/A
C12: Data Source | D12: Assessor, Inspection, Buyer, Lease
C13: Property Size (SF) | D13: ='Property Info'!B4
C14: Site Size (SF) | D14: ='Property Info'!B11 | V14: COMPARABLE SALE ADJUSTMENT GRID
C15: Parking Spaces | D15: 26
C16: Comments | D16: Owner-user daycare facility | E16: Single-tenant daycare facility 100% leased long-term to Prestige Preschool Academy, a national tenant. | G16: Daycare Facility, leased to a franchise tenant at TOS. | I16: Daycare facility, leased to a local tenant at TOS. | K16: Daycare building, local franchise lease at TOS. | M16: Daycare building, local franchise lease at TOS. | O16: Daycare facility, leased to a franchise daycare service on a 15 year agreement. Two 5-year renewal options available.
C17: Unadjusted Price Per SF | D17: =D9/D13 | F17: =E9/E13 | H17: =G9/G13 | J17: =I9/I13 | L17: =K9/K13 | N17: =M9/M13 | P17: =O9/O13
C18: Quantified Adjustments
C19: Property Rights Conveyed | D19: Leased Fee | E19: Leased Fee | F19: 0 | G19: Leased Fee | H19: 0 | I19: Leased Fee | J19: 0 | K19: Leased Fee | L19: 0 | M19: Leased Fee | N19: 0 | O19: Leased Fee
C20: Property Rights Conveyed Adjusted | F20: =IF(LEFT(CELL("format",F19),1)="P",F17*(1+F19),IF(LEFT(CELL("format",F19),1)="C",F17+F19)) | H20: =IF(LEFT(CELL("format",H19),1)="P",H17*(1+H19),IF(LEFT(CELL("format",H19),1)="C",H17+H19)) | J20: =IF(LEFT(CELL("format",J19),1)="P",J17*(1+J19),IF(LEFT(CELL("format",J19),1)="C",J17+J19)) | L20: =IF(LEFT(CELL("format",L19),1)="P",L17*(1+L19),IF(LEFT(CELL("format",L19),1)="C",L17+L19)) | N20: =IF(LEFT(CELL("format",N19),1)="P",N17*(1+N19),IF(LEFT(CELL("format",N19),1)="C",N17+N19)) | P20: =IF(LEFT(CELL("format",P19),1)="P",P17*(1+P19),IF(LEFT(CELL("format",P19),1)="C",P17+P19))
C21: Financing | D21: N/A | E21: Market-Based | F21: 0 | G21: Market-Based | H21: 0 | I21: Market-Based | J21: 0 | K21: Market-Based | L21: 0 | M21: Market-Based | N21: 0 | O21: N/A | P21: 0
C22: Financing Adjusted | F22: =IF(LEFT(CELL("format",F21),1)="P",F20*(1+F21),IF(LEFT(CELL("format",F21),1)="C",F20+F21)) | H22: =IF(LEFT(CELL("format",H21),1)="P",H20*(1+H21),IF(LEFT(CELL("format",H21),1)="C",H20+H21)) | J22: =IF(LEFT(CELL("format",J21),1)="P",J20*(1+J21),IF(LEFT(CELL("format",J21),1)="C",J20+J21)) | L22: =IF(LEFT(CELL("format",L21),1)="P",L20*(1+L21),IF(LEFT(CELL("format",L21),1)="C",L20+L21)) | N22: =IF(LEFT(CELL("format",N21),1)="P",N20*(1+N21),IF(LEFT(CELL("format",N21),1)="C",N20+N21)) | P22: =IF(LEFT(CELL("format",P21),1)="P",P20*(1+P21),IF(LEFT(CELL("format",P21),1)="C",P20+P21))
C23: Terms/Conditions of Sale | D23: N/A | E23: N/A | F23: 0 | G23: None | H23: 0 | I23: None | J23: 0 | K23: None | L23: 0 | M23: None | N23: 0 | O23: N/A | P23: -0.1
C24: Terms/Conditions of Sale Adjusted | F24: =IF(LEFT(CELL("format",F23),1)="P",F22*(1+F23),IF(LEFT(CELL("format",F23),1)="C",F22+F23)) | H24: =IF(LEFT(CELL("format",H23),1)="P",H22*(1+H23),IF(LEFT(CELL("format",H23),1)="C",H22+H23)) | J24: =IF(LEFT(CELL("format",J23),1)="P",J22*(1+J23),IF(LEFT(CELL("format",J23),1)="C",J22+J23)) | L24: =IF(LEFT(CELL("format",L23),1)="P",L22*(1+L23),IF(LEFT(CELL("format",L23),1)="C",L22+L23)) | N24: =IF(LEFT(CELL("format",N23),1)="P",N22*(1+N23),IF(LEFT(CELL("format",N23),1)="C",N22+N23)) | P24: =IF(LEFT(CELL("format",P23),1)="P",P22*(1+P23),IF(LEFT(CELL("format",P23),1)="C",P22+P23))
C25: Expenditures After Sale | D25: N/A | E25: N/A | F25: 0 | G25: None | H25: 0 | I25: None | J25: 0 | K25: None | L25: 0 | M25: None | N25: 0 | O25: N/A | P25: 0
C26: Expenditures After Sale Adjusted | F26: =IF(LEFT(CELL("format",F25),1)="P",F24*(1+F25),IF(LEFT(CELL("format",F25),1)="C",F24+F25)) | H26: =IF(LEFT(CELL("format",H25),1)="P",H24*(1+H25),IF(LEFT(CELL("format",H25),1)="C",H24+H25)) | J26: =IF(LEFT(CELL("format",J25),1)="P",J24*(1+J25),IF(LEFT(CELL("format",J25),1)="C",J24+J25)) | L26: =IF(LEFT(CELL("format",L25),1)="P",L24*(1+L25),IF(LEFT(CELL("format",L25),1)="C",L24+L25)) | N26: =IF(LEFT(CELL("format",N25),1)="P",N24*(1+N25),IF(LEFT(CELL("format",N25),1)="C",N24+N25)) | P26: =IF(LEFT(CELL("format",P25),1)="P",P24*(1+P25),IF(LEFT(CELL("format",P25),1)="C",P24+P25))
C27: Market Conditions | D27: N/A | E27: =E8 | F27: 0 | G27: =G8 | H27: 0 | I27: =I8 | J27: 0 | K27: =K8 | L27: 0 | M27: =M8 | N27: 0.03 | O27: =O8 | P27: 0
C28: Market Conditions Adjusted | F28: =IF(LEFT(CELL("format",F27),1)="P",F26*(1+F27),IF(LEFT(CELL("format",F27),1)="C",F26+F27)) | H28: =IF(LEFT(CELL("format",H27),1)="P",H26*(1+H27),IF(LEFT(CELL("format",H27),1)="C",H26+H27)) | J28: =IF(LEFT(CELL("format",J27),1)="P",J26*(1+J27),IF(LEFT(CELL("format",J27),1)="C",J26+J27)) | L28: =IF(LEFT(CELL("format",L27),1)="P",L26*(1+L27),IF(LEFT(CELL("format",L27),1)="C",L26+L27)) | N28: =IF(LEFT(CELL("format",N27),1)="P",N26*(1+N27),IF(LEFT(CELL("format",N27),1)="C",N26+N27)) | P28: =IF(LEFT(CELL("format",P27),1)="P",P26*(1+P27),IF(LEFT(CELL("format",P27),1)="C",P26+P27))
C29: Total Quantified Adjustment | F29: =IFERROR(TEXT(F28-F17,"$#,##0.00")&CHAR(10)&" or "&CHAR(10)&TEXT((F28-F17)/F17,"0.00%"),0) | H29: =IFERROR(TEXT(H28-H17,"$#,##0.00")&CHAR(10)&" or "&CHAR(10)&TEXT((H28-H17)/H17,"0.00%"),0) | J29: =IFERROR(TEXT(J28-J17,"$#,##0.00")&CHAR(10)&" or "&CHAR(10)&TEXT((J28-J17)/J17,"0.00%"),0) | L29: =IFERROR(TEXT(L28-L17,"$#,##0.00")&CHAR(10)&" or "&CHAR(10)&TEXT((L28-L17)/L17,"0.00%"),0) | N29: =IFERROR(TEXT(N28-N17,"$#,##0.00")&CHAR(10)&" or "&CHAR(10)&TEXT((N28-N17)/N17,"0.00%"),0) | P29: =IFERROR(TEXT(P28-P17,"$#,##0.00")&CHAR(10)&" or "&CHAR(10)&TEXT((P28-P17)/P17,"0.00%"),0)
C30: Quantitatively Adjusted Price | F30: =F28 | H30: =H28 | J30: =J28 | L30: =L28 | N30: =N28 | P30: =P28
C31: Qualitative Adjustments | F31: =SUM(F19:F29)+1 | H31: =SUM(H19:H29)+1 | J31: =SUM(J19:J29)+1 | L31: =SUM(L19:L29)+1 | N31: =SUM(N19:N29)+1 | P31: =SUM(P19:P29)+1
C32: Location | D32: Good | E32: Above-Average | F32: 0.05 | G32: Average | H32: 0.15 | I32: Average | J32: 0.15 | K32: Good | L32: 0.05 | M32: Good | N32: 0.05 | O32: Good | P32: -0.05
C33: Distance from Subject | D33: N/A | E33: 32 miles | G33: 16 miles | I33: 1/4 mile | K33: 1/4 mile | M33: 1/4 mile | O33: 24 miles
C34: Surrounding Land Uses | D34: Retail, residential, office | E34: Residential, retail | G34: Retail, office residential | I34: Retail, Office | K34: Retail, residential | M34: Office, flex, residential | O34: Residential, retail
C35: Quality/Condition of Surrounding Area | D35: Average to Good | E35: Average to Good | G35: Average to Good | I35: Average to Good | K35: Good to New | M35: Good to New | O35: Average to Very Good
C36: Access to Commercial Services/Amenities | D36: Good | E36: Average | G36: Good | I36: Good | K36: Good | M36: Average | O36: Good
C37: Visibility/Access | D37: Good: Primary thoroughfare | E37: Good: Primary thoroughfare | G37: Average: S. Lima St. | I37: Average: Oakridge Dr. & Mcmurry Ave. | K37: Good: Indiana St. & W 64th Ave. | M37: Average: Compark Blvd. | O37: Good - Access & Visibility from E 56th Ave.
C38: Demographics | D38: Population 3-Mile Radius: 60,202 MHHI 3-Mile Radius: $69,785 Pop. Growth (5-Yrs.): 9.65% | E38: Population 3-Miles: 45,519 MHHI 3-Mile Radius: $115,596 Pop. Growth (5-Yrs.): 9.59% | G38: Population 3-Miles: 60,848 MHHI 5-Mile Radius: $94,646 Pop. Growth (5-Yrs.): 6.84% | I38: Population 3-Miles: 83,390 MHHI 3-Mile Radius: $73,915 Pop. Growth (5-Yrs.): 8.97% | K38: Population 3-Miles: 57,214 MHHI 3-Mile Radius: $107,760 Pop. Growth (5-Yrs.): 4.49% | M38: Population 3-Miles: 55,098 MHHI 3-Mile Radius: $99,667 Pop. Growth (5-Yrs.): 9.59% | O38: Population 5-Mile Radius: 219,743 MHHI 3-Mile Radius: $58,707 Population Growth (5 Yrs.): 8.19%
C39: Property Size (SF) | D39: ='Property Info'!B4 | E39: =E13 | F39: 0 | G39: =G13 | H39: 0 | I39: =I13 | J39: 0 | K39: =K13 | L39: 0 | M39: =M13 | N39: -0.05 | O39: =O13 | P39: 0
C40: YOC / Condition | D40: 2019/Good | E40: 2018/Good | F40: 0 | G40: 2008/Above-Average | H40: 0.05 | I40: 2000 (Ren. 2019)/Good | J40: 0 | K40: 2019/New | L40: -0.05 | M40: 2015/Good | N40: 0 | O40: 2019/New | P40: 0
C41: Quality | D41: Good | E41: Average | F41: 0 | G41: Average | H41: 0 | I41: Average | J41: 0 | K41: Average | L41: 0 | M41: Average | N41: 0 | O41: Average | P41: 0
...

Sheet LA
B2: LEASE ABSTRACT
B3: Lessor | C3: Yafa Realty Investments, LLC | G3: Annual Rent Calc. Table
B4: Lessee | C4: Walker Component Group, Inc. | G4: Month | H4: Monthly Rent
B5: Building Size (SF) | C5: 33750 | G5: January | H5: 16120
B6: Lease Sign Date | C6: 42689 | G6: February | H6: 16120
B7: Lease Commencement Date | C7: 42689 | G7: March | H7: 16120
B8: Lease Expiration Date | C8: 46752 | G8: April | H8: 16120
B9: Base Lease Term (Months) | C9: =+(C8-C7)/365*12 | G9: May | H9: 16120
B10: 12 Months Contract Rental Income (Jan-Dec 2020) | C10: =H17 | G10: June | H10: 16120
B11: 12 Months Contract Rental Income (Jan-Dec 2020) | C11: =C10/C5 | G11: July | H11: 16120
B12: Base Rents | D12: Annual Rent (Lease) | G12: August | H12: 20230
B13: Year 1 (11/16-10/17) | C13: =D13/$C$5 | D13: 194062.5 | G13: September | H13: 20230
B14: Year 2 (11/17-10/18) | C14: =D14/$C$5 | D14: 194062.5 | G14: October | H14: 20230
B15: Year 3 (11/18-10/19) | C15: =D15/$C$5 | D15: 202500 | G15: November | H15: 20230
B16: Year 4 (11/19-10/20) | C16: =D16/$C$5 | D16: 202500 | G16: December | H16: 20230
B17: Year 5 (11/20-10/21) | C17: =D17/$C$5 | D17: 210937.5 | G17: Total | H17: =SUM(H5:H16)
B18: Frist Renewal Period | G18: PSF | H18: =H17/FE!C14
B19: Year 6 | C19: =D19/$C$5 | D19: 210937.5
B20: Year 7 | C20: =D20/$C$5 | D20: 219375
B21: Year 8 | C21: =D21/$C$5 | D21: 226125
B22: Year 9 | C22: =D22/$C$5 | D22: 232875
B23: Year 10 | C23: =D23/$C$5 | D23: 239625
B24: Year 11 | C24: =D24/$C$5 | D24: 242988
B29: Expense Structure | C29: NNN
B30: Landlord Expense Responsibilities | C30: Roof replacement/repair, structural damage
B31: Tenant Expense Responsibilities | C31: Tenant is responsible for all expenses directly, including taxes, insurance, CAM/repairs & maintenance, utilities and other expenses.
B32: Comments | C32: Initial 5-year term with two 5-year renewal options. First renewal option started as of the valuation date.
B33: Purchase Options | C33: None
B34: Termination Clause | C34: None
B35: Guarantor | C35: None
B36: Other | C36: Triple net agreement, sale-leaseback.
B37: Source | C37: Lease Agreement, owner, inspection, assessor data

Sheet LAG Percent
A2: COMPARABLE LEASE ADJUSTMENT GRID
A3: Characteristics | C3: Subject | E3: Lease 1 | G3: Lease 2 | I3: Lease 3 | K3: Lease 4 | M3: Rent 5
